Workbook

Sheet Buganvillas
A1: Property | B1: Bungavillas
A3: Asset description
A4: Asking price (€) | B4: 680000
A5: Offer price (€) | B5: 680000
A6: Total size (sqm) | B6: 1127
A7: Buildable area (sqm) | B7: 527
A8: €/bsqm | B8: =B5/B7 -> 1290.3226
A10: Financing
A11: Hard cost loan disposal | B11: 1
A12: Loan interest | B12: 0.06
A13: Term | B13: According to construction timeline
A14: Waiver principal payment | B14: 60 mo
A15: Principal payment term | B15: 36 mo
A16: Exit date | B16: 36
A18: Costs | B18: /sqm | C18: total
A19: Asset acquisition | B19: =B8 -> 1290.3226 | C19: =B19*$B$7 -> 680000
A20: Startup costs | B20: 400 | C20: =B20*$B$7 -> 210800
A21: External urbanization | B21: 0 | C21: =B21*$B$7 -> 0
A22: Hard costs | B22: 2500 | C22: =B22*$B$7 -> 1317500
A23: Soft costs | B23: =C23/B7 -> 450 | C23: =sum(C24:C26) -> 237150
A24: Arquitecture costs | C24: =$C$22*D24 -> 131750 | D24: 0.1 | E24: % of hard costs
A25: Licence costs & others | C25: =$C$22*D25 -> 39525 | D25: 0.03 | E25: % of hard costs
A26: Project management | C26: =$C$22*D26 -> 65875 | D26: 0.05 | E26: % of hard costs | F26: Capped
A27: TOTAL COSTS | B27: =sum(B19:B23)*B7 -> 2445450 | C27: =sum(C19:C23) -> 2445450
A29: Financials
A30: Estimated sale price | B30: /sqm | C30: total | D30: Margin | E30: % on cost
A31: No licence | B31: 6000 | C31: =B31*$B$7 -> 3162000 | D31: =C31-$C$27 -> 716550 | E31: =D31/$C$27 -> 0.29301356
A32: Licence obtained | B32: 6500 | C32: =B32*$B$7 -> 3425500 | D32: =C32-$C$27 -> 980050 | E32: =D32/$C$27 -> 0.40076469
A33: Construction started | B33: 7000 | C33: =B33*$B$7 -> 3689000 | D33: =C33-$C$27 -> 1243550 | E33: =D33/$C$27 -> 0.50851582
A34: Construction finalized | B34: 7500 | C34: =B34*$B$7 -> 3952500 | D34: =C34-$C$27 -> 1507050 | E34: =D34/$C$27 -> 0.61626694

Sheet El Cantal
A1: Property | B1: El Cantal, calle Leoni Benabu 41, 29018 Malaga
A3: Asset description
A4: Asking price (€) | B4: 540000
A5: Offer price (€) | B5: =B4 -> 540000
A6: Total size (sqm) | B6: 1006
A7: Buildable area (sqm) | B7: 500
A8: €/bsqm | B8: =B5/B7 -> 1080
A10: Financing
A11: Hard cost loan disposal | B11: 1
A12: Loan interest | B12: 0.06
A13: Term | B13: According to construction timeline
A14: Waiver principal payment | B14: 60 mo
A15: Principal payment term | B15: 36 mo
A16: Exit date | B16: 36
A18: Costs | B18: /sqm | C18: total
A19: Asset acquisition | B19: =B8 -> 1080 | C19: =B19*$B$7 -> 540000
A20: Agency cost | B20: 0.037 | C20: =B20*C19 -> 19980
A21: Startup costs | B21: =C21/B7 -> 198.8544 | C21: =SUM(C22:C25) -> 99427.2
A22: ITP | C22: =C19*D22 -> 37800 | D22: 0.07 | E22: % of asset costs
A23: Notary & Registro | C23: 2400 | D23: =C23/C19 -> 0.0044444444 | E23: % of asset costs
A24: Legal fees | C24: =D24*C19*1.21 -> 5227.2 | D24: 0.008 | E24: % of asset costs
A25: Other costs | C25: =C19*D25 -> 54000 | D25: 0.1 | E25: % of asset costs
A26: Hard costs | B26: 2500 | C26: =sum(C27:C29) -> 1310000 | D26: bank financing (approx 60-80%)
A27: Construction (all incl.) | B27: 2500 | C27: =B27*B7 -> 1250000 | E27: % of hard costs
A28: Insurance (seguro decenal) | C28: =D28*$C$27 -> 10000 | D28: 0.008 | E28: % of hard costs
A29: Municipal taxes | C29: =D29*$C$27 -> 50000 | D29: 0.04 | E29: % of hard costs
A30: Soft costs | B30: =C30/B7 -> 550.2 | C30: =sum(C31:C34) -> 275100
A31: Arquitecture costs | C31: =$C$26*D31 -> 131000 | D31: 0.1 | E31: % of hard costs
A32: Aparejador | C32: =$C$26*D32 -> 65500 | D32: 0.05 | E32: % of hard costs
A33: Licence costs & others | C33: =$C$26*D33 -> 39300 | D33: 0.03 | E33: % of hard costs
A34: Project management | C34: =$C$26*D34 -> 39300 | D34: 0.03 | E34: % of hard costs
A35: Provisions & contingencies | C35: =D35*C26 -> 131000 | D35: 0.1 | E35: % of hard costs
A36: TOTAL COSTS | C36: =C19+C20+C21+C35+C26+C30 -> 2375507.2
A38: Financials | H38: 0.21
A39: Estimated sale price | B39: €/sqm | C39: total | D39: margin | E39: sales commission | F39: sales commission € | G39: margin post commission | H39: margin post taxes | I39: % on cost | J39: est. timeline | K39: time since purchase | L39: Timing | M39: TRI
A40: No licence, only project | B40: 5500 | C40: =B40*$B$7 -> 2750000 | D40: =C40-$C$36 -> 374492.8 | E40: 0.05 | F40: =C40*E40 -> 137500 | G40: =D40-F40 -> 236992.8 | H40: =G40*(1-$H$38) -> 187224.31 | I40: =H40/$C$36 -> 0.078814458 | J40: Q1 2026 | K40: approx 3 months | L40: 3
A41: Licence obtained | B41: 6500 | C41: =B41*$B$7 -> 3250000 | D41: =C41-$C$36 -> 874492.8 | E41: 0.05 | F41: =C41*E41 -> 162500 | G41: =D41-F41 -> 711992.8 | H41: =G41*(1-$H$38) -> 562474.31 | I41: =H41/$C$36 -> 0.23678072 | J41: Q4 2026 | K41: approx 12 months | L41: 12
A42: Construction started | B42: 7000 | C42: =B42*$B$7 -> 3500000 | D42: =C42-$C$36 -> 1124492.8 | E42: 0.05 | F42: =C42*E42 -> 175000 | G42: =D42-F42 -> 949492.8 | H42: =G42*(1-$H$38) -> 750099.31 | I42: =H42/$C$36 -> 0.31576386 | J42: Q1 2027 | K42: approx 14 months | L42: 14
A43: Construction finalized | B43: 8000 | C43: =B43*$B$7 -> 4000000 | D43: =C43-$C$36 -> 1624492.8 | E43: 0.05 | F43: =C43*E43 -> 200000 | G43: =D43-F43 -> 1424492.8 | H43: =G43*(1-$H$38) -> 1125349.3 | I43: =H43/$C$36 -> 0.47373012 | J43: Q2 2028 | K43: approx 28-32 months | L43: 32
A45: Current
...

Sheet Summary
A1: Project name | B1: Villa Buganvilleas
A2: Adress | B2: Buganvillas 14, 29018 Malaga
A3: Hypothesis | B3: =Hypothesis!B3 -> Base case
A5: SIMPLIFIED P&L | B5: € | C5: € / sqm
A6: SELLING PRICE | B6: =Hypothesis!B19 -> 3952500 | C6: =B6/Hypothesis!$B$10 -> 7500
A8: Property price | B8: =Hypothesis!B23 -> 625000 | C8: =B8/Hypothesis!$B$10 -> 1185.9583
A9: Taxes & commissions | B9: =sum(Hypothesis!B24:B26) -> 133450 | C9: =B9/Hypothesis!$B$10 -> 253.22581
A10: Set up costs | B10: =Hypothesis!B27 -> 22753.5 | C10: =B10/Hypothesis!$B$10 -> 43.175522
A11: Soft costs - Architecture, permits, etc | B11: =Hypothesis!B34 -> 306980.45 | C11: =B11/Hypothesis!$B$10 -> 582.5056
A12: Hard costs - Construction | B12: =Hypothesis!B29 -> 1753592.5 | C12: =B12/Hypothesis!$B$10 -> 3327.5
A13: Hard costs - Contingencies | B13: =Hypothesis!B33 -> 87679.625 | C13: =B13/Hypothesis!$B$10 -> 166.375
A14: TOTAL COSTS | B14: =SUM(B8:B13) -> 2929456.1 | C14: =SUM(C8:C13) -> 5558.7402
A16: SELLING COMMISSION | B16: =Hypothesis!B55 -> 276675 | C16: =B16/Hypothesis!$B$10 -> 525
A18: FINANCING COSTS | B18: =Hypothesis!B58 -> 146472.8 | C18: =B18/Hypothesis!$B$10 -> 277.93701
A20: NET PROFIT BEFORE TAXES | B20: =B6-B14-B16-B18 -> 599896.12 | C20: =B20/Hypothesis!$B$10 -> 1138.3228
A22: Taxes & commissions | B22: =B20*25% -> 149974.03 | C22: =B22/Hypothesis!$B$10 -> 284.5807
A23: ITP devolution | B23: =Hypothesis!B62 -> 131250 | C23: =B23/Hypothesis!$B$10 -> 249.05123
A24: NET PROFIT AFTER TAXES | B24: =B20-B22+B23 -> 581172.09 | C24: =B24/Hypothesis!$B$10 -> 1102.7933
A26: Equity invested | B26: =Hypothesis!B66 -> 1175863.6
A27: ROE | B27: =B24/B26 -> 0.49425129
A29: Project duration | B29: 3
A30: IRR | B30: =IF(B29=3,Hypothesis!B79,Hypothesis!C79) -> 0.22239572

Sheet Hypothesis
A1: Project name | B1: =Summary!B1 -> Villa Buganvilleas
A2: Adress | B2: =Summary!B2 -> Buganvillas 14, 29018 Malaga
A3: Hypothesis | B3: Base case
A5: ASSUMPTIONS | D5: SCENARII | E5: sale price / sqm | F5: PEM costs / sqm
A6: Tipologia edificacion | B6: Unifamiliar aislada UAS-4 | D6: Worst case | E6: 6500 | F6: 2750
A7: Superficie parcela adoptada | B7: 1127 | C7: m2 | D7: Base case | E7: 7500 | F7: 2750
A8: Ratio edificabilidad | B8: 0.244 | D8: Best case | E8: 8000 | F8: 2750
A9: Superficie edificabilidad total | B9: =B7*B8 -> 274.988 | C9: m2
A10: Superficie construida total | B10: =B11+B12 -> 527 | C10: m2
A11: Construida sobre rasante | B11: =527/2 -> 263.5 | C11: m2
A12: Construida bajo rasante | B12: =527/2 -> 263.5 | C12: m2
A13: Exterior jardines y ZZCC urbanizacion | B13: =B7-B11 -> 863.5 | C13: m2
A15: SALES | B15: Revenue (excl. VAT) | C15: sale price / sqm
A16: I. Villa sale (without licence) | B16: =C16*$B$10 -> 3162000 | C16: =C17-500 -> 6000
A17: II. Villa sale (with licence) | B17: =C17*$B$10 -> 3425500 | C17: =C18-500 -> 6500
A18: III. Villa sale (construction started) | B18: =C18*$B$10 -> 3689000 | C18: =C19-500 -> 7000
A19: IV. Villa sale (construction finalized) | B19: =C19*$B$10 -> 3952500 | C19: =VLOOKUP(B3,D5:F8,2,FALSE) -> 7500
A21: COSTS | B21: Costs (excl. VAT) | C21: cost / sqm | D21: %
A22: Hard cost - land purchase | B22: =sum(B23:B26) -> 758450 | C22: =B22/$B$10 -> 1439.1841
A23: Land asking price | B23: 625000
A24: ITP (taxes) | B24: =B23*D24 -> 131250 | D24: 0.21 | E24: to be recuperated EOY
A25: Notary & registro | B25: 2200
A26: Sales commission | B26: =B23*D26 -> 0 | D26: 0
A27: Hard cost - setup costs | B27: =B22*D27 -> 22753.5 | D27: 0.03
A28: Hard cost - urbanization costs | B28: 0 | C28: 0 | D28: 0
A29: Hard cost - construction costs | B29: =sum(B30:B32) -> 1753592.5 | C29: =B29/$B$10 -> 3327.5
A30: PEM costs | B30: =C30*$B$10 -> 1449250 | C30: =VLOOKUP(B3,D5:F8,3,FALSE) -> 2750
A31: PEC costs | B31: =C31*$B$10 -> 144925 | C31: =C30*D31 -> 275 | D31: 0.1
A32: Other costs (insurance, taxes) | B32: =D32*(B30+B31) -> 159417.5 | C32: =B32/$B$10 -> 302.5 | D32: 0.1
A33: Hard cost - contingencies | B33: =D33*B29 -> 87679.625 | D33: 0.05
A34: Soft cost - All costs | B34: =sum(B35:B40) -> 306980.45 | C34: =B34/B10 -> 582.5056 | D34: 0.1
A35: Arquitecture - project | B35: =D35*$B$29 -> 35071.85 | C35: =$C$30*D35 -> 55 | D35: 0.02
A36: Arquitecture - ejecucion | B36: =D36*$B$29 -> 35071.85 | C36: =$C$30*D36 -> 55 | D36: 0.02
A37: Aparejador | B37: =D37*$B$29 -> 35071.85 | C37: =$C$30*D37 -> 55 | D37: 0.02
A38: Paisajismo | B38: =D38*$B$29 -> 87679.625 | C38: =$C$30*D38 -> 137.5 | D38: 0.05
A39: Licence costs & others | B39: =D39*$B$29 -> 52607.775 | C39: =$C$30*D39 -> 82.5 | D39: 0.03
A40: Project management | B40: ='Project management'!B13 -> 61477.5 | C40: =B40/B10 -> 116.6556 | D40: =C40/C29 -> 0.035058031
A42: TOTAL COSTS | B42: =B22+B27+B28+B29+B33+B34 -> 2929456.1 | C42: =B42/B10 -> 5558.7402 | D42: =B42/B19 -> 0.74116536
A44: GROSS PROFIT | B44: Gross profit (excl. taxes) | C44: Gross profit / revenue
A45: =A16 -> I. Villa sale (without licence) | B45: =B16-$B$42 -> 232543.92 | C45: =B45/B16 -> 0.073543303
...

Sheet Comparables
A1: Project name | B1: Villa El Cantal
A2: Adress | B2: Leoni Benabu 41, 29018 Malaga
A3: Hypothesis | B3: Base
H4: coefficient
A5: MARKET COMPARABLES | B5: Location | C5: Year sold | D5: Status | E5: Sale price | F5: sqm built | G5: sale price / sqm | H5: sales status | I5: localisation | J5: quality / premium | K5: real sale price / sqm | L5: reason | M5: link
A6: Pinares Hill #1 | B6: Pinares de San Anton | C6: - | D6: Reserved | E6: 4800000 | F6: 486 | G6: =E6/F6 -> 9876.5432 | H6: 0.9 | I6: 1 | J6: 0.9 | K6: =G6*H6/I6/J6 -> 9876.5432 | L6: Same location | M6: https://www.idealista.com/inmueble/108642153/
A7: Pinares Hill #2 | B7: Pinares de San Anton | C7: 2025 | D7: Reserved | E7: 3800000 | F7: 412 | G7: =E7/F7 -> 9223.301 | H7: 0.9 | I7: 1 | J7: 0.9 | K7: =G7*H7/I7/J7 -> 9223.301 | L7: Same location | M7: https://resources.lucasfox.com/property/mlg52486-floorplans.pdf
A8: Pinares Hill #3 | B8: Pinares de San Anton | C8: 2025 | D8: For sale | E8: 2475000 | F8: 309 | G8: =E8/F8 -> 8009.7087 | H8: 0.8 | I8: 1 | J8: 0.9 | K8: =G8*H8/I8/J8 -> 7119.7411 | L8: Same location | M8: https://www.idealista.com/fr/inmueble/106417665/
A9: Pinares Hill #4 | B9: Pinares de San Anton | C9: 2025 | D9: For sale | E9: 2800000 | F9: 341 | G9: =E9/F9 -> 8211.1437 | H9: 0.8 | I9: 1 | J9: 0.9 | K9: =G9*H9/I9/J9 -> 7298.7944 | L9: Same location | M9: https://www.idealista.com/fr/inmueble/105059159/
A10: Villa Los Alcornoques | B10: Benahavis | C10: 2023 | D10: Sold | E10: 7200000 | F10: 627 | G10: =E10/F10 -> 11483.254 | H10: 1 | I10: 1.3 | J10: 1 | K10: =G10*H10/I10/J10 -> 8833.272 | L10: Marbella (+) | M10: https://flow81.com/project/villa-alcornoque/
A11: Villa Las Nubes | B11: Sotogrande | C11: 2022 | D11: Sold | E11: 4500000 | F11: 439 | G11: =E11/F11 -> 10250.569 | H11: 1 | I11: 1.3 | J11: 1 | K11: =G11*H11/I11/J11 -> 7885.0534 | L11: Marbella (+) | M11: https://flow81.com/project/villa-calle-grazalema/
A12: Villa en el Candado | B12: El Candado | C12: - | D12: Construction in progress | E12: 2450000 | F12: 420 | G12: =E12/F12 -> 5833.3333 | H12: 0.85 | I12: 0.95 | J12: 0.9 | K12: =G12*H12/I12/J12 -> 5799.2203 | L12: Close location | M12: https://www.lucasfox.es/comprar-vivienda/espana/costa-del-sol/malaga/pinares-de-san-anton-el-candado/casa-villa/mlg44689.html
A13: Leoni Benabu (neighbour) | B13: Pinares de San Anton | C13: - | D13: Construction in progress | E13: 6500000 | F13: 660 | G13: =E13/F13 -> 9848.4848 | H13: 0.85 | I13: 1 | J13: 1 | K13: =G13*H13/I13/J13 -> 8371.2121 | L13: Same location | M13: -
A14: Pinares house | B14: Pinares de San Anton | C14: - | D14: For sale | E14: 4295000 | F14: 516 | G14: =E14/F14 -> 8323.6434 | H14: 0.8 | I14: 1 | J14: 0.7 | K14: =G14*H14/I14/J14 -> 9512.7353 | L14: Same location | M14: https://www.idealista.com/fr/inmueble/107064042/
A15: Pinares house | B15: Pinares de San Anton | C15: - | D15: For sale | E15: 3450000 | F15: 706 | G15: =E15/F15 -> 4886.6856 | H15: 0.8 | I15: 1 | J15: 0.7 | K15: =G15*H15/I15/J15 -> 5584.7835 | L15: Same location | M15: https://www.idealista.com/fr/inmueble/108640971/
A16: Pinares house | B16: Pinares de San Anton | C16: - | D16: For sale | E16: 3000000 | F16: 400 | G16: =E16/F16 -> 7500 | H16: 0.8 | I16: 1 | J16: 0.7 | K16: =G16*H16/I16/J16 -> 8571.4286 | L16: Same location | M16: https://www.idealista.com/fr/inmueble/109457637/
A17: Pinares house | B17: Pinares de San Anton | C17: - | D17: For sale | E17: 4000000 | F17: 830 | G17: =E17/F17 -> 4819.2771 | H17: 0.8 | I17: 1 | J17: 0.7 | K17: =G17*H17/I17/J17 -> 5507.7453 | L17: Same location | M17: https://www.idealista.com/fr/inmueble/82580369/
A18: Casa Farber | B18: Pinares de San Anton | C18: 2024 | D18: Sold | E18: 2500000 | F18: 450 | G18: =E18/F18 -> 5555.5556 | H18: 1 | I18: 1 | J18: 0.8 | K18: =G18*H18/I18/J18 -> 6944.4444 | L18: Same location | M18: -
J20: average | K20: =average(K6:K19) -> 7732.9442
J21: median | K21: =MEDIAN(K6:K18) -> 7885.0534
J22: highest point | K22: =max(K6:K18) -> 9876.5432
J23: lowest point | K23: =min(K6:K18) -> 5507.7453

Sheet Architecture

Sheet Project management
A1: Project name | B1: =Hypothesis!B1 -> Villa Buganvilleas
A2: Adress | B2: =Hypothesis!B2 -> Buganvillas 14, 29018 Malaga
A3: Hypothesis | B3: =Hypothesis!B3 -> Base case
A5: PROJECT MANAGEMENT
A6: Principio: en cuanto se tenga el proyecto de ejecucion
A8: Revision del proyecto de ejecucion | B8: 3000
A9: Proceso de licitacion con las constructoras
A10: Ejecucion de la obra | B10: =C10*Hypothesis!B30 -> 43477.5 | C10: 0.03
A11: Final de la obra | B11: 15000
A12: Postventa
A13: TOTAL COSTS | B13: =sum(B8:B12) -> 61477.5

Sheet Hypothesis_worst
A1: Project name | B1: Villa El Cantal
A2: Adress | B2: Leoni Benabu 41, 29018 Malaga
A3: Hypothesis | B3: Worst
A5: ASSUMPTIONS
A6: Tipologia edificacion | B6: Unifamiliar aislada UAS
A7: Superficie parcela adoptada | B7: 1006.75 | C7: m2
A8: Ratio edificabilidad | B8: 0.25
A9: Superficie edificabilidad total | B9: =B7*B8 -> 251.6875 | C9: m2
A10: Superficie construida total | B10: =B11+B12 -> 503.38 | C10: m2
A11: Construida sobre rasante | B11: 251.69 | C11: m2
A12: Construida bajo rasante | B12: 251.69 | C12: m2
A13: Exterior jardines y ZZCC urbanizacion | B13: 755.06 | C13: m2
A15: SALES | B15: Revenue (excl. VAT) | C15: sale price / sqm
A16: I. Villa sale (without licence) | B16: =C16*$B$10 -> 2013520 | C16: 4000
A17: II. Villa sale (with licence) | B17: =C17*$B$10 -> 2265210 | C17: 4500
A18: III. Villa sale (construction started) | B18: =C18*$B$10 -> 2516900 | C18: 5000
A19: IV. Villa sale (construction finalized) | B19: =C19*$B$10 -> 2768590 | C19: 5500
A21: COSTS | B21: Costs (excl. VAT) | C21: cost / sqm | D21: % | F21: PROJECT MANAGEMENT | G21: Costs (excl. VAT) | H21: % | K21: EXAMPLE | L21: Costs (excl. VAT) | M21: %
A22: Hard cost - land purchase | B22: =sum(B23:B26) -> 599980 | C22: =B22/$B$7 -> 595.95729 | F22: =A29&" planned" -> Hard cost - construction costs planned | G22: =B29 -> 1674996.9 | K22: =F22 -> Hard cost - construction costs planned | L22: =G22 -> 1674996.9
A23: Land asking price | B23: 540000 | F23: Project management commission | G23: =G22*H23 -> 83749.848 | H23: 0.05 | I23: Fixed | K23: Hard cost - construction costs real | L23: 1450000
A24: ITP (taxes) | B24: =B23*D24 -> 37800 | D24: 0.07 | F24: Bonus - 15% of savings vs budget | H24: 0.15 | I24: Max 20k€ | K24: Project management commission | L24: =L22*M24 -> 83749.848 | M24: 0.05
A25: Notary & registro | B25: 2200 | D25: =B25/B22 -> 0.0036667889 | F25: Bonus - 2k€ per month ahead of schedule | I25: Max 10k€ | K25: Bonus - 15% of savings vs budget | L25: =M25*(L22-L23) -> 33749.543 | M25: 0.15 | N25: Max 20k€
A26: Sales commission | B26: =B23*D26 -> 19980 | D26: 0.037 | K26: Bonus - 2k€ per month ahead of schedule | L26: 4000 | N26: Max 10k€
A27: Hard cost - setup costs | B27: =B22*D27 -> 17999.4 | D27: 0.03 | F27: Payment steps | K27: TOTAL COMMISSION | L27: =L24+L25+L26 -> 121499.39
A28: Hard cost - urbanization costs | B28: 0 | C28: 0 | D28: 0 | F28: Contract signed | G28: 0.1
A29: Hard cost - construction costs | B29: =sum(B30:B32) -> 1674996.9 | C29: =B29/$B$10 -> 3327.5 | F29: Permit approved | G29: 0.1
A30: PEM costs | B30: =C30*$B$10 -> 1384295 | C30: 2750 | F30: Contractor selected | G30: 0.15
A31: PEC costs | B31: =C31*$B$10 -> 138429.5 | C31: =C30*D31 -> 275 | D31: 0.1 | F31: 50% construction progress | G31: 0.3
A32: Other costs (insurance, taxes) | B32: =D32*(B30+B31) -> 152272.45 | C32: =B32/$B$10 -> 302.5 | D32: 0.1 | F32: Structure topped out | G32: 0.15
A33: Hard cost - contingencies | B33: =D33*B29 -> 83749.848 | D33: 0.05 | F33: Delivery | G33: 0.2
A34: Soft cost - All costs | B34: =sum(B35:B38) -> 351749.36 | C34: =B34/B10 -> 698.775 | D34: 0.1 | G34: =SUM(G28:G33) -> 1
A35: Arquitecture costs | B35: =D35*$B$29 -> 167499.7 | C35: =$C$30*D35 -> 275 | D35: 0.1
A36: Aparejador | B36: =D36*$B$29 -> 83749.848 | C36: =$C$30*D36 -> 137.5 | D36: 0.05
A37: Licence costs & others | B37: =D37*$B$29 -> 50249.908 | C37: =$C$30*D37 -> 82.5 | D37: 0.03
A38: Project management | B38: =D38*$B$29 -> 50249.908 | C38: =$C$30*D38 -> 82.5 | D38: 0.03
A40: TOTAL COSTS | B40: =B22+B27+B28+B29+B33+B34 -> 2728475.6 | C40: =B40/B10 -> 5420.3098 | D40: =B40/B19 -> 0.98551088
A42: GROSS PROFIT | B42: Gross profit (excl. taxes) | C42: Gross profit / revenue
A43: =A16 -> I. Villa sale (without licence) | B43: =B16-$B$40 -> -714955.56 | C43: =B43/B16 -> -0.35507745
A44: =A17 -> II. Villa sale (with licence) | B44: =B17-$B$40 -> -463265.56 | C44: =B44/B17 -> -0.20451329
A45: =A18 -> III. Villa sale (construction started) | B45: =B18-$B$40 -> -211575.56 | C45: =B45/B18 -> -0.084061964
...

Sheet Hypothesis_best
A1: Project name | B1: Villa El Cantal
A2: Adress | B2: Leoni Benabu 41, 29018 Malaga
A3: Hypothesis | B3: Best
A5: ASSUMPTIONS
A6: Tipologia edificacion | B6: Unifamiliar aislada UAS
A7: Superficie parcela adoptada | B7: 1006.75 | C7: m2
A8: Ratio edificabilidad | B8: 0.25
A9: Superficie edificabilidad total | B9: =B7*B8 -> 251.6875 | C9: m2
A10: Superficie construida total | B10: =B11+B12 -> 503.38 | C10: m2
A11: Construida sobre rasante | B11: 251.69 | C11: m2
A12: Construida bajo rasante | B12: 251.69 | C12: m2
A13: Exterior jardines y ZZCC urbanizacion | B13: 755.06 | C13: m2
A15: SALES | B15: Revenue (excl. VAT) | C15: sale price / sqm
A16: I. Villa sale (without licence) | B16: =C16*$B$10 -> 2768590 | C16: 5500
A17: II. Villa sale (with licence) | B17: =C17*$B$10 -> 3271970 | C17: 6500
A18: III. Villa sale (construction started) | B18: =C18*$B$10 -> 3775350 | C18: 7500
A19: IV. Villa sale (construction finalized) | B19: =C19*$B$10 -> 4530420 | C19: 9000
A21: COSTS | B21: Costs (excl. VAT) | C21: cost / sqm | D21: % | F21: PROJECT MANAGEMENT | G21: Costs (excl. VAT) | H21: % | K21: EXAMPLE | L21: Costs (excl. VAT) | M21: %
A22: Hard cost - land purchase | B22: =sum(B23:B26) -> 599980 | C22: =B22/$B$7 -> 595.95729 | F22: =A29&" planned" -> Hard cost - construction costs planned | G22: =B29 -> 1674996.9 | K22: =F22 -> Hard cost - construction costs planned | L22: =G22 -> 1674996.9
A23: Land asking price | B23: 540000 | F23: Project management commission | G23: =G22*H23 -> 83749.848 | H23: 0.05 | I23: Fixed | K23: Hard cost - construction costs real | L23: 1450000
A24: ITP (taxes) | B24: =B23*D24 -> 37800 | D24: 0.07 | F24: Bonus - 15% of savings vs budget | H24: 0.15 | I24: Max 20k€ | K24: Project management commission | L24: =L22*M24 -> 83749.848 | M24: 0.05
A25: Notary & registro | B25: 2200 | D25: =B25/B22 -> 0.0036667889 | F25: Bonus - 2k€ per month ahead of schedule | I25: Max 10k€ | K25: Bonus - 15% of savings vs budget | L25: =M25*(L22-L23) -> 33749.543 | M25: 0.15 | N25: Max 20k€
A26: Sales commission | B26: =B23*D26 -> 19980 | D26: 0.037 | K26: Bonus - 2k€ per month ahead of schedule | L26: 4000 | N26: Max 10k€
A27: Hard cost - setup costs | B27: =B22*D27 -> 17999.4 | D27: 0.03 | F27: Payment steps | K27: TOTAL COMMISSION | L27: =L24+L25+L26 -> 121499.39
A28: Hard cost - urbanization costs | B28: 0 | C28: 0 | D28: 0 | F28: Contract signed | G28: 0.1
A29: Hard cost - construction costs | B29: =sum(B30:B32) -> 1674996.9 | C29: =B29/$B$10 -> 3327.5 | F29: Permit approved | G29: 0.1
A30: PEM costs | B30: =C30*$B$10 -> 1384295 | C30: 2750 | F30: Contractor selected | G30: 0.15
A31: PEC costs | B31: =C31*$B$10 -> 138429.5 | C31: =C30*D31 -> 275 | D31: 0.1 | F31: 50% construction progress | G31: 0.3
A32: Other costs (insurance, taxes) | B32: =D32*(B30+B31) -> 152272.45 | C32: =B32/$B$10 -> 302.5 | D32: 0.1 | F32: Structure topped out | G32: 0.15
A33: Hard cost - contingencies | B33: =D33*B29 -> 83749.848 | D33: 0.05 | F33: Delivery | G33: 0.2
A34: Soft cost - All costs | B34: =sum(B35:B38) -> 351749.36 | C34: =B34/B10 -> 698.775 | D34: 0.1 | G34: =SUM(G28:G33) -> 1
A35: Arquitecture costs | B35: =D35*$B$29 -> 167499.7 | C35: =$C$30*D35 -> 275 | D35: 0.1
A36: Aparejador | B36: =D36*$B$29 -> 83749.848 | C36: =$C$30*D36 -> 137.5 | D36: 0.05
A37: Licence costs & others | B37: =D37*$B$29 -> 50249.908 | C37: =$C$30*D37 -> 82.5 | D37: 0.03
A38: Project management | B38: =D38*$B$29 -> 50249.908 | C38: =$C$30*D38 -> 82.5 | D38: 0.03
A40: TOTAL COSTS | B40: =B22+B27+B28+B29+B33+B34 -> 2728475.6 | C40: =B40/B10 -> 5420.3098 | D40: =B40/B19 -> 0.60225665
A42: GROSS PROFIT | B42: Gross profit (excl. taxes) | C42: Gross profit / revenue
A43: =A16 -> I. Villa sale (without licence) | B43: =B16-$B$40 -> 40114.443 | C43: =B43/B16 -> 0.014489124
A44: =A17 -> II. Villa sale (with licence) | B44: =B17-$B$40 -> 543494.44 | C44: =B44/B17 -> 0.16610618
A45: =A18 -> III. Villa sale (construction started) | B45: =B18-$B$40 -> 1046874.4 | C45: =B45/B18 -> 0.27729202
...
